# 비동기

브라우저 환경에서는 얼마나 걸릴지 예측할 수 없는 요소가 많다. 대표적으로는 사용자 입력 대기와 서버 API 응답, 파일 조회 등이 있다. 이러한 유형의 작업들을 자바스크립트 엔진이 코드를 실행할 때 동기적으로 처리하게 된다면 프로그램을 사용하지도 못하고 **모든 작업이 마무리될 때까지 무한정 대기**하게 된다. 이건 당연하게도 너무 비효율적이다. 자바스크립트가 멀티 스레드의 언어였다면 다른 스레드에 해당 작업을 넘기고, 사용자의 interaction을 할 수 있었겠지만 안타깝게도 자바스크립트는 **싱글 스레드 언어**이다.

이러한 한계를 보완하기 위해 Event Loop가 나타나게 되었다. 해결 방법은 꽤 단순하다. ‘지금’이 아닌 **‘나중에’** 처리하겠다는 전략이다. 나중에 처리하는 코드는 `ajax`, `setTimeout`과 같은 Web API이다.



1. Web API를 실행하면 브라우저 환경에서 해당 작업을 수행한다. [Web API는 어떻게 동작하지?](##Web API)
2. 작업이 완료되면 **callback** 함수를 callback queue에 실행 대기 상태로 넣어준다.
3. 자바스크립트 엔진이 모든 코드를 다 실행해서 call stack이 비게 되면, callback queue에서 순차적으로 하나씩 꺼내어 **‘나중에’** 실행하게 된다.

이걸 이미지로 표현하자면 아래와 같다.
![42eatw03fcha0e1qcrf0](https://github.com/kjhwert/blogs/assets/40383255/496749e8-267e-4e30-b962-f1de18cdf0c7)

해당 이미지에는 callback queue가 microtask queue, macrotask queue 두 가지로 나뉘어져 있지만 이 부분은 이후에 설명하겠다.

# Callback

‘지금’이 아닌 ‘나중에’가 자바스크립트의 비동기 처리 전략이라는 걸 알게 되었다. 나중에 돌아오기 위해 자바스크립트는 callback 함수를 달아서 활용하게 된다. 바로 1세대 비동기 처리 방법인 것이다. 
callback은 비동기를 표현하고 관리하는 가장 기본적이고 일반적인 방법이다. 자바스크립트 개발자는 의도하지 않아도 자연스럽게 callback 패턴을 활용해서 흐름을 제어하곤 한다.
자바스크립트의 함수가 일급 함수인 덕분에 이러한 패턴이 생겨날 수 있었고, 여전히 비동기를 표현하기에 적절하고 유용한 표현이다. 하지만, 비동기의 depth가 깊어지면 생각은 조금 달라진다.

### 가독성
필요한 데이터를 얻기 위해 API 호출을 한다고 가정하자.
하지만 해당 API를 호출하기 위해 필요한 데이터 또한 요청을 통해 얻어야한다고 하면 아래와 같은 형태의 코드가 구성된다.
```typescript
listen("click", function handler(e) {
    ajax("https://some.url.1", (res) => {
        // calculate response data
        const result = calculatedData;
        
        ajax(`https://some.url.2?someData=${result}`, (res) => {
            console.log('활용할 데이터: ', res)  
        })
    })
})
```
조금 가독성이 떨어지기는 하지만, 그래도 아직까지는 이해하기 크게 어렵지 않다.
하지만 현재 코드는 에러를 고려하지 않았다. API 호출이 실패할 수도 있기 때문에 이 부분도 추가해보자.
```typescript
listen("click", function handler(e) {
    ajax("https://some.url.1", (res) => {
        // calculate response data
        const result = calculatedData;
        
        ajax(`https://some.url.2?someData=${result}`, (res) => {
            console.log('활용할 데이터: ', res)
        }, (err) => {
            console.error('https://some.url.2', err)
        })
    }, (err) => {
        console.error('https://some.url.1', err)
    })
})
```
에러를 분할 콜백으로 제공한다고 했을 때 에러 우선 콜백보다는 그나마 낫지만 이조차도 머리가 조금씩 어지러워진다.
이 상황에서 또 다른 API가 추가된다고 하면 자연스럽게 함수를 나누려는 시도를 하게 된다.
```typescript
listen("click", function handler(e) {
    someUrl1((res1) => someUrl2(res1, (res2) => someUrl3(res2, (res3) => {
        console.log('내가 필요한 데이터: ', res3)
    })))
})

function someUrl1(callback) {
    ajax("https://some.url.1", (res) => {
        // calculate response data
        const result = calculatedData;
        callback(result)
    }, (err) => {
        console.error('https://some.url.1', err)
    })
}

function someUrl2(params, callback) {
    ajax(`https://some.url.2?someData=${params}`, (res) => {
        // calculate response data
        const result = calculatedData;
        callback(result)
    }, (err) => {
        console.error('https://some.url.2', err)
    })
}

function someUrl3(params, callback) {
    ajax(`https://some.url.3?someData=${params}`, (res) => {
        // calculate response data
        const result = calculatedData;
        callback(result)
    }, (err) => {
        console.error('https://some.url.2', err)
    })
}
```
someUrl1 -> someUrl2 -> someUrl3 함수를 호출하면서 결국 원하는 데이터를 얻긴했지만
각 함수에서는 어떤 처리를 하는지 확인하기 위해서는 에디터를 이리저리 옮겨가며 확인해야 한다. 코드에 익숙치 않다면
이 흐름을 파악하고 따라가는 데에 더 많은 어려움을 겪을 것이다. 정리하자면, 콜백을 통한 비동기 처리는
비동기의 흐름을 **비선형적, 비순차적인 방향**으로 나타내기 때문에 코드를 이해하기 어렵다.

### 제어의 역전
우리가 흔히 상품을 구매할 때 정해진 절차대로 진행을 해야한다. 구매할 상품을 주문하고, 주문내역을 토대로 결제를 진행한다.
결제가 완료되면 주문내역을 확인할 수 있고 결제 중에 쿠폰이나 포인트 등을 사용했다면 업데이트도 필요하다. 이는 코드로 다음과 같이 표현할 수 있다.
```typescript
api.createOrder(cart,function payment(){
    api.processedToPayment(function orderSummary(){
        api.orderSummery(function updateWallet(){
            api.updateWallet();
        });     
    })
} );
```
출처: [callback-hell-and-inversion-of-control](https://dailylearn.hashnode.dev/callback-hell-and-inversion-of-control)

코드를 전부 작성하긴 했지만 이 코드가 항상 정상적으로 실행될거라고 믿은 나머지 발생할 수 있는 **여러 예외 상황에 대한 고려**가 전혀 되어있지 않다. 
예외 케이스를 몇 가지 열거해보자면
1. callback을 너무 일찍 부른다. callback으로 전달할 데이터가 충분히 처리되지 않았음에도 callback 함수를 호출하게 되면 필요한 데이터를 확인할 수 없다.
2. callback을 너무 늦게 호출하거나 아예 호출하지 않는다. callback의 순서에 따라 코드가 처리되기 때문에 사용자는 무한정 대기할 수 밖에 없다.
3. callback을 너무 적게 또는 너무 많이 부른다. 가령 callback을 많이 호출한다면 한 상품에 대해 주문이나 결제를 여러번 진행하게 된다.
4. `api.*` 함수 내부적으로 에러가 발생했지만 무시하고 callback을 전달하는 경우. 이 경우에는 주문이 실패했지만 정상처리 됐다고 판단해 결제나 주문내역 처리 등을 진행하게 된다.

이런 케이스들을 고려하다보면 callback 마다 수많은 예외 케이스에 대한 방어 코드를 덧붙여 두어야 할 것이다.

왜 이런 케이스가 발생하게 되었을까? `api.*` 함수의 관리 주체는 내가 아닌 외부이기 때문이다(그 외부는 사내에 다른 팀일수도, 오픈 소스 라이브러리일 수도 있다).
외부 개발자가 잘못 개발하여 버그가 발생한다면 내 코드 또한 정상적으로 처리가 불가능하다. 하지만 이런 상황은 내가 컨트롤 할 수 없다.
그저 외부에서 가져온 유틸리티 함수가 callback을 정확한 시점에 호출되길 바라는 수밖에 없다. 이러한 상황을 제어의 역전이라고 한다.
매번 비동기 함수를 호출할 때마다 콜백 함수에 반복적인 방어 로직을 작성하려고 하면 점점 유지보수가 어려운 코드가 되어가는걸 발견하게 된다.  

이런 문제를 염두해두고, promise는 어떻게 문제를 해결했는지, callback 문제를 모두 보완했는지 살펴보자.

# Promise


콜백은 제어의 역전이라고 했는데, 프라미스를 통해 다시 제어권을 획득하게 되었다.

책에서 설명하고 있는 예시가 promise에 대해 접근하기에 참 좋은 예시라는 생각이다.
> 시나리오는 이렇다. 동네 패스트푸드 점에서 나는 치즈 버거 세트를 먹기로 한다. 카운터 점원에게 세트 메뉴를 주문하고
> 5,500원을 결제한다. 동시에 거래가 시작된다.
> 주문이 밀리면 치즈 버거가 바로 안나올 수 있다. 점원은 내게 치즈 버거 대신 주문번호가 적힌 영수증을 건네준다.
> 이 주문번호는 일종의 IOU(당신에게 빚졌어요)로, 언젠가는 반드시 내게 치즈 버거를 주겠다는 **약속(promise)**이다.
> ...
> 기다리면서 친구한테 문자 메시지를 보내는 등 다른 일을 한다. 나는 아직 받지 못한 미래의 치즈버거가 눈 앞에 있는 양 사고한다.
> 내 두뇌는 이미 영수증에 적힌 주문 번호를 치즈 버거의 자리끼움(placeholder)으로 인식하는 모양이다. 이 자리끼움은 시간 독립적인 값, 즉 **미래값**이다.
 
책에서는 치즈 버거 세트를 구매하는 상황을 통해 promise를 설명한다.
세트를 구매하고 나면 영수증을 받는다. 이 영수증이 반드시 버거 세트를 주겠다는 약속이다.
영수증을 들고 기다리면서 나는 다른 일을 한다. 
책의 예시가 promise를 참 잘 설명해주었다고 생각한다. 말 그대로 약속이다. 비동기가 안전하게 처리될 것이라는 약속.
물론 처리는 이행 혹은 거절이긴 하겠지만, 상태를 분명히 전달해주고 또한 한번 결정된 상태는 불변하므로 안전하다. 

1. 어떻게 다시 제어권을 획득했다고 할 수 있을까?
promise로 부터 성공과 실패라는 이벤트를 구독한 상태에서 callback을 심어두었다. 성공과 실패는 코드가 처리되면 반드시 하나는 호출될 것이고
이벤트 구독을 통해 우리가 제어하고 있는 callback으로 가져오는 것이다.

2. 관심사 분리. callback에서 두 비동기 처리가 모두 완료되면 두 데이터를 활용해 계산하는 로직이 있다고 한다면,
callback에 다른 callback이 호출되어 데이터가 구성되어 있는지 확인이 필요하다. 하지만 promise.all을 활용하면
데이터 구성을 확인할 필요가 없다.

Promise는 귀결되고나면 외부적으로 불변상태이므로 변경될 일은 없다. 이 말은 promise의 상태가 resolved 혹은 rejected로 귀결되고 나면 다른 상태로 바뀔 일이 없다는 말이다.
```typescript
new Promise((resolve, reject) => {
    resolve('완료')
    
    reject('완료 아닌데?') // 무시됨
    resolve('데이터 바꿀건데?') // 무시됨
})
```

그럼 promise를 통해 callback에서 이야기했던 문제들이 모두 해소되었을까? 
#### callback을 너무 일찍 부른다.
then()을 호출하면 프라미스가 귀결된 이후라 해도 then()에 건넨 콜백은 항상 비동기적으로만 부른다. 굳이 setTimeout(..., 0)과 같은 꼼수를 쓸 필요가 없다.
#### callback을 너무 늦게 호출하거나 아예 호출하지 않는다.
then()에 등록한 콜백은 새 프라미스가 생성되면서 resolve(), reject() 중 어느 한쪽은 자동 호출하도록 스케줄링 된다. 이렇게 스케줄링된 두 콜백은 다음 비동기 시점에 예상대로 실행된다.
프라미스가 귀결되면 then()에 등록된 콜백들이 그다음 비동기 기회가 찾아왔을 때 순서대로 실행되며 어느 한 콜백 내부에서 다른 콜백의 호출에 영향을 주거나 지연시킬 일은 있을 수 없다.
```typescript
p.then(() => {
    p.then(() => {
        console.log('C')
    })
    console.log('A')
})

p.then(() => {
    console.log('B')
})
// A B C
```
여기서 프라미스 작동 원리 덕분에 "C"가 끼어들어 B보다 빨리 호출될 가능성은 없다.
하지만 프라미스 체이닝에서는 프라미스 스케줄링에 조금 더 주의를 기울여야 한다.
아래 코드를 보면 p1 -> p3 -> p2이기 때문에 로그가 B, A로 출력될거라 생각할 수 있지만,
프라미스는 모두 비동기 잡 큐에 의해 처리되므로 queue에 쌓이는 순서는 p1 -> p2 -> p3가 된다.
따라서 출력은 A, B가 된다.
```typescript
const p3 = new Promise(res => {
    res("B")
})

const p1 = new Promise(res => {
    res(p3)
})

const p2 = new Promise(res => {
    res('A')
})

p1.then((value) => {
    console.log(value)
})

p2.then((value) => {
    console.log(value)
})

// A B
```
#### callback을 너무 적게 또는 너무 많이 부른다.
promise.then()의 호출은 당연히 한 번이다. 그리고 프라미스는 단 한번만 귀결된다. 어떤 이유로든 promise 내부에서 resolve, reject를 여러번 호출한다고 하더라도
귀결된 상태가 변경되거나 재호출되지 않는다.

#### 에러/예외
프라미스가 생성 중 또는 귀결을 기다리는 도중 언제라도 TypeError, ReferenceError 등의 자바스크립트 에러가 나면 예외를 잡아 주어진 프라미스를 강제로 버린다.
그렇다면 promise.then()에서 예외가 발생하면 어떻게 될까?
```typescript
const p = new Promise((resolve) => {
    resolve()
})

p.then(() => {
    console.log(msg)
}, () => {
    console.log('rejected') // 호출되지 않는다.
})

// Promise Rejected: ReferenceError: msg is not defined
```
p.then()가 반환한 또 다른 프라미스에서 TypeError 에외가 나면서 버려지게 된다. then()에서 에러가 발생하는 경우 rejected로 귀결시키면 되지 않을까 싶기는 하지만,
그렇게 된다면 프라미스의 귀결된 상태는 불변이다는 명제가 지켜지지 않게 된다. 또한 프라미스에 then() 콜백이 여러개 등록되어 있는 상태에서 어떤 콜백은 호출하고 어떤 콜백은 호출하지 않는다면 혼란을 야기할 수 있다.

## Promise.resolve()
1. thenable이지만 Promise가 아닌 값에 대해 프라미스로 정규화할 수 있다.
```typescript
const p = {
    then: function(cb, errcb) {
        cb(42);
        errcb("사악한 미소");
    }
};

p.then(function fulfilled(value) {
    console.log('fulfilled',value)
}, function rejected(error) {
    console.log('error',error) // 호출되면 안된다.
})
```
p는 thenable 이지만 프라미스처럼 작동하지 않는다. 이러한 케이스가 있다는건 그만큼 프라미스에 대한 신뢰가 낮아질 수 있다는 말이다. 하지만, 어떤 데이터여도 Promise.resolve()에 넣으면
정규화하므로 안전한 결과를 기대할 수 있다.
```typescript
Promise.resolve(p).then(...)
```
2. 특정 함수가 경우에 따라 즉시 값을 반환하거나 Promise를 반환하는 경우라면 Promise.resolve()로 감싸면 반환값을 항상 Promise로 고정할 수 있다.
3. Promise.resolve는 진짜 프라미스를 받으면 도로 뱉어내고, 데너블을 받으면 일단 한번 풀어보고 아니면 원하는 값이 나올때까지 재귀적으로 계속 풀어본다.

## Promise Chaining
> 비동기의 연쇄를 나타낼 때 Promise chaining을 쓰면 좋겠지만, 그 상황이 언제일까..?

당연히 연속적으로 API 호출을 하는 상황이겠지만, 두 세번 정도의 api chaining 이라면 await 으로 나타내도 크게 문제 없지 않을까?...
각각의 API에 대해 예외처리를 해야할 때 유용할까?
프라미스 체이닝은 다단게 비동기 시퀀스에서 흐름 제어 뿐만 아니라 단계와 단계 사이에 메시지를 전달하는 채널로도 쓰인다.
프라미스 연쇄의 어느 단계에서 문제가 발생하면 에러/예외는 프라미스 단위로 한정되므로 전체 연쇄 어느 곳에서 난 에러라도 모두 잡아 바로 그 지점부터 리셋을 하여 연쇄를 다시 정상 가동시킨다.
```typescript
Promise.resolve('https://some.url')
// 2단계
.then(res => {
    foo.bar(); // 정의되지 않았으니 에러 발생
    
    return Promise.resolve('https://some.url2')
})
// 3단계
.then(function fulfilled() {
    // 실행되지 않는다.
}, function rejected(err) {
    console.log('error', err) // foo is not defined
    
    return 42;
})
// 4단계
.then((msg) => {
    console.log(msg) // 42
})
```
2단계에서 에러가 나면 3단계 reject가 이를 잡아 필요시 어떤 값(42)을 반환해 다음 4단계의 프라미스가 이루어지게 한다. 이런 식으로 전체 연쇄는 다시 resolve 상태로 돌아간다.

#### 프라미스 체이닝에서의 에러처리
프라미스 체이닝에서의 에러처리는 프라미스당 예외처리(catch)를 하고, 이어서 핸들러를 진행하면 된다.
```typescript
new Promise((resolve, reject) => {
    throw new Error('에러 발생!')
}).catch(err => {
    alert('에러가 처리되었습니다.')
}).then(() => {
    alert('다음 핸들러가 정상적으로 처리됩니다.')
})
```
하지만 catch에서도 에러가 발생한다면, 그 다음 핸들러는 resolve가 아닌 reject(catch)에서 처리된다.
```typescript
new Promise((resolve, reject) => {
    throw new Error('에러 발생!')
}).catch(err => {
    throw new Error('앗 또 에러가 발생했네요')
}).then(() => {
    // 호출되지 않습니다.
}).catch(() => {
    alert('자꾸 에러가 발생하네요')
})
```
---

You Don’t Know JS [this와 객체 프로토타입, 비동기와 성능]
https://ko.javascript.info/callbacks
https://ko.javascript.info/promise-basics
https://ko.javascript.info/event-loop
[https://inpa.tistory.com/entry/🌐-js-async](https://inpa.tistory.com/entry/%F0%9F%8C%90-js-async)
https://www.youtube.com/watch?v=8aGhZQkoFbQ
